----------------------------------------
127.0.0.1 - - [17/Mar/2015 02:18:14] "GET /users/login HTTP/1.0" 500 -
----------------------------------------
Exception happened during processing of request from ('127.0.0.1', 57606)
Traceback (most recent call last):
  File "/usr/lib/python2.7/SocketServer.py", line 295, in _handle_request_noblock
    self.process_request(request, client_address)
  File "/usr/lib/python2.7/SocketServer.py", line 321, in process_request
    self.finish_request(request, client_address)
  File "/usr/lib/python2.7/SocketServer.py", line 334, in finish_request
    self.RequestHandlerClass(request, client_address, self)
  File "/usr/lib/python2.7/SocketServer.py", line 651, in __init__
    self.finish()
  File "/usr/lib/python2.7/SocketServer.py", line 710, in finish
    self.wfile.close()
  File "/usr/lib/python2.7/socket.py", line 279, in close
    self.flush()
  File "/usr/lib/python2.7/socket.py", line 303, in flush
    self._sock.sendall(view[write_offset:write_offset+buffer_size])
error: [Errno 32] Broken pipe
